<?xml version="1.0" encoding="utf-8"?>
<robot name="panda_gripper">
  <link name="world">
	</link>

	<joint name="pris_joint_1" type="prismatic">
		<parent link="world"/>
		<child link="link1"/>
		<origin rpy="0.0 0.0 0.0" xyz="0.0 0.0 0.0"/>
		<axis xyz="1 0 0"/>
		<dynamics damping="0.01" friction="0.01"/>
		<limit lower="-10" upper="10" velocity="1" effort="2"/>
	</joint>

  <link name="link1">
	</link>

	<joint name="pris_joint_2" type="prismatic">
		<parent link="link1"/>
		<child link="link2"/>
		<origin rpy="0.0 0.0 0.0" xyz="0.0 0.0 0.0"/>
		<axis xyz="0 1 0"/>
		<dynamics damping="0.01" friction="0.01"/>
		<limit lower="-10" upper="10" velocity="1" effort="2"/>
	</joint>

  <link name="link2">
	</link>

  <joint name="pris_joint_3" type="prismatic">
		<parent link="link2"/>
		<child link="link3"/>
		<origin rpy="0.0 0.0 0.0" xyz="0.0 0.0 0.0"/>
		<axis xyz="0 0 1"/>
		<dynamics damping="0.01" friction="0.01"/>
		<limit lower="-10" upper="10" velocity="1" effort="2"/>
	</joint>

  <link name="link3">
	</link>

  <joint name="rev_joint1" type="revolute">
    <parent link="link3"/>
    <child link="link4"/>
    <origin rpy="0.0 0.0 0.0" xyz="0.0 0.0 0"/>
		<axis xyz="0 0 1"/>
    <limit lower="-3.14" upper="3.14" velocity="0.001" effort="2"/>
	</joint>

  <link name="link4">
	</link>

  <joint name="rev_joint2" type="revolute">
    <parent link="link4"/>
    <child link="link5"/>
    <origin rpy="0.0 3.14 0.0" xyz="0.0 0.0 0"/>
		<axis xyz="0 1 0"/>
    <limit lower="-3.14" upper="3.14" velocity="0.001" effort="2"/>
	</joint>

  <link name="link5">
	</link>
  
  <joint name="rev_joint3" type="revolute">
    <parent link="link5"/>
    <child link="panda_hand"/>
    <origin rpy="0.0 3.14 0.0" xyz="0.0 0.0 0"/>
		<axis xyz="1 0 0"/>
    <limit lower="-3.14" upper="3.14" velocity="0.001" effort="2"/>
	</joint>

  <link name="panda_hand">
    <visual>
      <geometry>
        <mesh filename="package://franka_description/meshes/visual/hand.dae"/>
      </geometry>
    </visual>
    <collision>
      <geometry>
        <mesh filename="package://franka_description/meshes/collision/hand.obj"/>
      </geometry>
    </collision>
  </link>

  
  <link name="panda_leftfinger">
    <visual>
      <geometry>
        <mesh filename="package://franka_description/meshes/visual/finger.dae"/>
      </geometry>
    </visual>
    <collision>
      <geometry>
        <mesh filename="package://franka_description/meshes/collision/finger.obj"/>
      </geometry>
    </collision>
  </link>


  <link name="panda_rightfinger">
    <visual>
      <origin rpy="0 0 3.14159265359" xyz="0 0 0"/>
      <geometry>
        <mesh filename="package://franka_description/meshes/visual/finger.dae"/>
      </geometry>
    </visual>
    <collision>
      <origin rpy="0 0 3.14159265359" xyz="0 0 0"/>
      <geometry>
        <mesh filename="package://franka_description/meshes/collision/finger.obj"/>
      </geometry>
    </collision>
  </link>



  <joint name="panda_finger_joint1" type="prismatic">
    <parent link="panda_hand"/>
    <child link="panda_leftfinger"/>
    <origin rpy="0 0 0" xyz="0 0 0.0584"/>
    <axis xyz="0 1 0"/>
    <dynamics damping="10.0"/>
    <limit effort="30" lower="0.0" upper="0.04" velocity="0.2"/>
  </joint>


  <joint name="panda_finger_joint2" type="prismatic">
    <parent link="panda_hand"/>
    <child link="panda_rightfinger"/>
    <origin rpy="0 0 0" xyz="0 0 0.0584"/>
    <axis xyz="0 -1 0"/>
    <dynamics damping="10.0"/>
    <limit effort="30" lower="0.0" upper="0.04" velocity="0.2"/>
    <mimic joint="panda_finger_joint1"/>
  </joint>
</robot>